Workbook
Name condition_1085B4A664DA38CA9CAB09C9B0B2E251: 'Conditions List'!$C$7:$C$7
Name condition_146DD677425832B1B256FDC2A6A4A1EA: 'Conditions List'!$C$24:$O$24
Name condition_1FDC4E4E7716327980BE0EB5F85DDAB1: 'Conditions List'!$C$13:$D$13
Name condition_2926A45167D03778A2AE22BD860CDE82: 'Conditions List'!$C$10:$C$10
Name condition_308E72ECF4B933A6A3C645A8467BC71E: 'Conditions List'!$C$3:$G$3
Name condition_3710C0A819223E3487D01309378226DC: 'Conditions List'!$C$31:$E$31
Name condition_457FDBB5A67735DAB66C4713D23E75A2: 'Conditions List'!$C$4:$C$4
Name condition_5C293928C78C306A9965E2888BA342B3: 'Conditions List'!$C$9:$C$9
Name condition_6175D3D1E7333AEDB59353B9CA9482FD: 'Conditions List'!$C$22:$O$22
Name condition_66EB70B5C5A43B5B8FF26B31B1817A2C: 'Conditions List'!$C$29:$X$29
Name condition_67B14A71EFCC3F83990EA6A2D66BFEA2: 'Conditions List'!$C$12:$C$12
Name condition_680D3B7617DD3F0ABAA8270BBDCAD9BB: 'Conditions List'!$C$30:$X$30
Name condition_681821EFDCEC3C3B93CC6D793E12D966: 'Conditions List'!$C$25:$O$25
Name condition_7FDFA689F55D37C8BCE13934576805D0: 'Conditions List'!$C$5:$F$5
Name condition_821ADFECFB703A71867851F81F19CF78: 'Conditions List'!$C$21:$O$21
Name condition_851AB4D926583A659171AB36316BE900: 'Conditions List'!$C$15:$O$15
Name condition_8617D3E9125F33BC88F0F75538411BAF: 'Conditions List'!$C$8:$C$8
Name condition_89D3B1E0A9DA3555B19AC4B84605A88B: 'Conditions List'!$C$1:$C$1
Name condition_8E5E53BB8B9535AFA1C23BCA9C5DD874: 'Conditions List'!$C$20:$O$20
Name condition_9FBC0C23B75D3104B2C40A8BEBCAAFB9: 'Conditions List'!$C$19:$O$19
Name condition_A8D0A7B1410F39BAB2C826C292BDD6AC: 'Conditions List'!$C$26:$O$26
Name condition_BE605DFE9D193FD9A5D762C182A4D048: 'Conditions List'!$C$11:$C$11
Name condition_C0EAB11EDA263845BE4CA17346F5CF86: 'Conditions List'!$C$27:$O$27
Name condition_C196059A8C3D3CAC96A0D72243A2599D: 'Conditions List'!$C$23:$O$23
Name condition_C921CBEA72BB3E85B3BE9EB274D77809: 'Conditions List'!$C$28:$C$28
Name condition_CE1DE48E77B733A4A7A298C30F08B784: 'Conditions List'!$C$6:$C$6
Name condition_D45499349AFB3761AE10B8529FEA03C2: 'Conditions List'!$C$16:$O$16
Name condition_DF5CC8DF05DF3C579F7588A18BC94C31: 'Conditions List'!$C$18:$O$18
Name condition_E3429B7064A735D8AE16EA22E3B72AE9: 'Conditions List'!$C$14:$D$14
Name condition_E36409CE568836BAA4F1A31911103C9D: 'Conditions List'!$C$17:$O$17
Name condition_E91D7D3AED243B3C9270F77B3B13D394: 'Conditions List'!$C$2:$D$2
Name t_012109DDB92E37C782942343C3FAA646: 'Dropdown Lists'!$C$54:$E$54
Name t_01BA699F340E3B1C80CC2D963BF4E23C: 'Dropdown Lists'!$C$22:$BY$22
Name t_041CCA92EE77300983BA260D5471D2F6: 'Dropdown Lists'!$C$49:$I$49
Name t_0BBD854D7BD33808B617FC1FB91FF644: 'Dropdown Lists'!$C$56:$I$56
Name t_0F3F86297DFD333C9666B531B0353B3C: 'Dropdown Lists'!$C$35:$D$35
Name t_102B0F8B23393DE98AFB27DE3D742D48: 'Dropdown Lists'!$C$15:$F$15
Name t_12264466A77D3B36AC2DAA034A1A5FE2: 'Dropdown Lists'!$C$20:$G$20
Name t_1636BD1CFBD53CA59961F2B345D4FEEB: 'Dropdown Lists'!$C$55:$D$55
Name t_1AE68FAE4C233AF2AAD93B3EC17512F8: 'Dropdown Lists'!$C$42:$D$42
Name t_1CFBAFB02535396A90C8042DFA8BC3FD: 'Dropdown Lists'!$C$47:$C$47
Name t_1DEE4A266E48377DA726E10015B5D56F: 'Dropdown Lists'!$C$65:$HU$65
Name t_210AC56516C831C3B975426026564B85: 'Dropdown Lists'!$C$4:$H$4
Name t_241370342FE93115B86141B16F0D66B3: 'Dropdown Lists'!$C$46:$F$46
Name t_24E9F6E5671238AEB940988128184600: 'Dropdown Lists'!$C$18:$AV$18
Name t_275F523CC3DA36BF82F6D13DA3C4DE73: 'Dropdown Lists'!$C$51:$G$51
Name t_3210EDB3F0FF3AABAF0449B028E64379: 'Dropdown Lists'!$C$30:$J$30
Name t_358C61997BEA39239CE0596AA5F8E1FD: 'Dropdown Lists'!$C$52:$I$52
Name t_35F193C6A7E13FE09ED9BAE2922D841A: 'Dropdown Lists'!$C$59:$G$59
Name t_395E9262634839C383597E24E1E36964: 'Dropdown Lists'!$C$68:$AHP$68
Name t_3F8AAC6653D43B55B905228704037B79: 'Dropdown Lists'!$C$57:$I$57
Name t_4BDCEE54E14C361091E3B7E7BC6BFA58: 'Dropdown Lists'!$C$8:$F$8
Name t_4D0B0322FE473E23B6C86F1C3A06BA2B: 'Dropdown Lists'!$C$25:$J$25
Name t_4D36BB0BF9A633DDA10597E97D2DE70D: 'Dropdown Lists'!$C$12:$G$12
Name t_4E6356A2F95E3E55B9B8EF4AFCA2B468: 'Dropdown Lists'!$C$63:$F$63
Name t_4E8EB62C344D3136894C37789B634AC8: 'Dropdown Lists'!$C$9:$K$9
Name t_4FCF4D5E513C3C149F22DA945CD3A4F9: 'Dropdown Lists'!$C$24:$I$24
Name t_548CA8DB852B3D74B0E67F20F3C16269: 'Dropdown Lists'!$C$29:$J$29
Name t_5848D61FB8923C738935B53104584AF7: 'Dropdown Lists'!$C$37:$C$37
Name t_59D4DF059C473EBE9972B0D6D3C6BFD5: 'Dropdown Lists'!$C$16:$E$16

Sheet Template
A1: Processing Results | E1: Product Identity | T1: Product Description | DS1: Product Detail | EQ1: Sale Property (At Least One, At Most Two) | FE1: Variations | GI1: Offer | GM1: Qualifications
A2: Goods Id | B2: Sku Id | C2: Status | D2: Details | E2: Category | F2: Category Name | G2: Product type | H2: Customization processing technique | I2: Primary technique | J2: Secondary technique | K2: Secondary technique | L2: Product Name | M2: Contribution Goods | N2: Contribution SKU | O2: Update or Add | P2: Goods Id | Q2: Sku Id | R2: Brand | S2: Trademark | T2: Product Description | U2: Bullet Point | V2: Bullet Point | W2: Bullet Point | X2: Bullet Point | Y2: Bullet Point | Z2: Bullet Point | AA2: Detail Images URL | AB2: Detail Images URL | AC2: Detail Images URL | AD2: Detail Images URL | AE2: Detail Images URL | AF2: Detail Images URL | AG2: Detail Images URL | AH2: Detail Images URL | AI2: Detail Images URL | AJ2: Detail Images URL | AK2: Detail Images URL | AL2: Detail Images URL | AM2: Detail Images URL | AN2: Detail Images URL | AO2: Detail Images URL | AP2: Detail Images URL | AQ2: Detail Images URL | AR2: Detail Images URL | AS2: Detail Images URL | AT2: Detail Images URL | AU2: Detail Images URL | AV2: Detail Images URL | AW2: Detail Images URL | AX2: Detail Images URL | AY2: Detail Images URL | AZ2: Detail Images URL | BA2: Detail Images URL | BB2: Detail Images URL | BC2: Detail Images URL | BD2: Detail Images URL | BE2: Detail Images URL | BF2: Detail Images URL | BG2: Detail Images URL | BH2: Detail Images URL | BI2: Detail Images URL | BJ2: Detail Images URL | BK2: Detail Images URL | BL2: Detail Images URL | BM2: Detail Images URL | BN2: Detail Images URL | BO2: Detail Images URL | BP2: Detail Images URL | BQ2: Detail Images URL | BR2: Detail Images URL | BS2: Detail Images URL | BT2: Detail Images URL | BU2: Detail Images URL | BV2: Detail Images URL | BW2: Detail Images URL | BX2: Detail Images URL | BY2: Detail Images URL | BZ2: Detail Images URL | CA2: Detail Images URL | CB2: Detail Images URL | CC2: Detail Images URL | CD2: Detail Images URL | CE2: Detail Images URL | CF2: Detail Images URL | CG2: Detail Images URL | CH2: Detail Images URL | CI2: Detail Images URL | CJ2: Detail Images URL | CK2: Detail Images URL | CL2: Detail Images URL | CM2: Detail Images URL | CN2: Detail Images URL | CO2: Detail Images URL | CP2: Detail Images URL | CQ2: Detail Images URL | CR2: Detail Images URL | CS2: Detail Images URL | CT2: Detail Images URL | CU2: Detail Images URL | CV2: Detail Images URL | CW2: Detail Images URL | CX2: Detail Images URL | CY2: Detail Images URL | CZ2: Detail Images URL | DA2: Detail Images URL | DB2: Detail Images URL | DC2: Detail Images URL | DD2: Detail Images URL | DE2: Detail Images URL | DF2: Detail Images URL | DG2: Detail Images URL | DH2: Detail Images URL | DI2: Detail Images URL | DJ2: Detail Images URL | DK2: Detail Images URL | DL2: Detail Images URL | DM2: Detail Images URL | DN2: Detail Images URL | DO2: Detail Images URL | DP2: Detail Images URL | DQ2: Detail Images URL | DR2: Detail Video URL | DS2: 19 - Style | DT2: 423 - Holidays | DU2: 423 - Holidays | DV2: 423 - Holidays | DW2: 423 - Holidays | DX2: 423 - Holidays | DY2: 127 - Mounting Type | DZ2: 121 - Material | EA2: 130 - Theme | EB2: 2232 - Whether There Are Feathers | EC2: 2233 - Feather Material | ED2: 1561 - Power Supply | EE2: 1132 - Operating Voltage | EF2: 1562 - Battery Quantity | EG2: 137 - Battery Type | EH2: 1563 - Battery Included or Not | EI2: 1485 - Plug Type | EJ2: 2147 - Rechargeable Battery | EK2: 2154 - Solar Battery Type | EL2: 111 - Batteries Included | EM2: 2028 - Battery Capacity (mAh) - value | EN2: 2028 - Battery Capacity (mAh) - unit | EO2: 3673 - Language Type | EP2: 7644 - Does It Contain Real Plants? | EQ2: Variation Theme | ER2: Color | ES2: Size | ET2: Style | EU2: Material | EV2: Flavors | EW2: Applicable People | EX2: Capacity | EY2: Composition | EZ2: Weight | FA2: Items | FB2: Quantity | FC2: Model | FD2: Hair Length | FE2: SKU Images URL | FF2: SKU Images URL | FG2: SKU Images URL | FH2: SKU Images URL | FI2: SKU Images URL | FJ2: SKU Images URL | FK2: SKU Images URL | FL2: SKU Images URL | FM2: SKU Images URL | FN2: SKU Images URL | FO2: Dimensions | FP2: Quantity | FQ2: Base Price - USD | FR2: Reference Link | FS2: List Price - USD | FT2: Weight - lb | FU2: Length - in | FV2: Width - in | FW2: Height - in | FX2: SKU type | FY2: Individually packed | FZ2: Total packaging quantity | GA2: Packaging unit | GB2: Total item quantity | GC2: Item unit | GD2: Net content | GE2: Total net content | GF2: Net content unit | GG2: External Product ID Type | GH2: External Product ID | GI2: Shipping Template | GJ2: Handling Time | GK2: Import Designation | GL2: Fulfillment Channel | GM2: Country/Region of Origin | GN2: Province of Origin | GO2: SKU Packaging Information (with visible label) | GP2: SKU Packaging Information (with visible label) | GQ2: SKU Packaging Information (with visible label) | GR2: SKU Packaging Information (with visible label) | GS2: SKU Packaging Information (with visible label) | GT2: SKU Packaging Information (with visible label) | GU2: SKU Packaging Information (with visible label) | GV2: SKU Packaging Information (with visible label) | GW2: SKU Packaging Information (with visible label) | GX2: SKU Packaging Information (with visible label) | GY2: SKU Packaging Information (with visible label) | GZ2: SKU Packaging Information (with visible label) | HA2: SKU Packaging Information (with visible label) | HB2: SKU Packaging Information (with visible label) | HC2: SKU Packaging Information (with visible label) | HD2: SKU Packaging Information (with visible label) | HE2: SKU Packaging Information (with visible label) | HF2: SKU Packaging Information (with visible label) | HG2: SKU Packaging Information (with visible label) | HH2: SKU Packaging Information (with visible label) | HI2: SKU Packaging Information (with visible label) | HJ2: SKU Packaging Information (with visible label) | HK2: SKU Packaging Information (with visible label) | HL2: SKU Packaging Information (with visible label) | HM2: SKU Packaging Information (with visible label) | HN2: SKU Packaging Information (with visible label) | HO2: SKU Packaging Information (with visible label) | HP2: SKU Packaging Information (with visible label) | HQ2: SKU Packaging Information (with visible label) | HR2: SKU Packaging Information (with visible label) | HS2: SKU Packaging Information (with visible label) | HT2: SKU Packaging Information (with visible label) | HU2: SKU Packaging Information (with visible label) | HV2: SKU Packaging Information (with visible label) | HW2: SKU Packaging Information (with visible label) | HX2: SKU Packaging Information (with visible label) | HY2: SKU Packaging Information (with visible label) | HZ2: SKU Packaging Information (with visible label) | IA2: SKU Packaging Information (with visible label) | IB2: SKU Packaging Information (with visible label) | IC2: SKU Packaging Information (with visible label) | ID2: SKU Packaging Information (with visible label) | IE2: SKU Packaging Information (with visible label) | IF2: SKU Packaging Information (with visible label) | IG2: SKU Packaging Information (with visible label) | IH2: Origin Label & Manufacturer Information | II2: Origin Label & Manufacturer Information | IJ2: Origin Label & Manufacturer Information | IK2: Origin Label & Manufacturer Information | IL2: Origin Label & Manufacturer Information | IM2: Product Guide - English | IN2: California Proposition 65 Warning Type | IO2: California Proposition 65 Chemical Names
A3: Reserved line, prohibit any operation. | B3: Reserved line, prohibit any operation. | C3: Reserved line, prohibit any operation. | D3: Reserved line, prohibit any operation. | E3: eyJ0ZW1wbGF0ZV9pZCI6NTY0ODQzMzk2ODEwNTI3LCJ0ZW1wbGF0ZV9sYW5ndWFnZSI6ImVuIiwic2l0ZV9pZCI6MTAwLCJ2ZXJzaW9uIjoiMy4wLjAiLCJ0eXBlIjowfQ== | F3: Reserved line, prohibit any operation. | G3: Reserved line, prohibit any operation. | H3: Reserved line, prohibit any operation. | I3: Reserved line, prohibit any operation. | J3: Reserved line, prohibit any operation. | K3: Reserved line, prohibit any operation. | L3: Reserved line, prohibit any operation. | M3: Reserved line, prohibit any operation. | N3: Reserved line, prohibit any operation. | O3: Reserved line, prohibit any operation. | P3: Reserved line, prohibit any operation. | Q3: Reserved line, prohibit any operation. | R3: Reserved line, prohibit any operation. | S3: Reserved line, prohibit any operation. | T3: Reserved line, prohibit any operation. | U3: Reserved line, prohibit any operation. | V3: Reserved line, prohibit any operation. | W3: Reserved line, prohibit any operation. | X3: Reserved line, prohibit any operation. | Y3: Reserved line, prohibit any operation. | Z3: Reserved line, prohibit any operation. | AA3: Reserved line, prohibit any operation. | AB3: Reserved line, prohibit any operation. | AC3: Reserved line, prohibit any operation. | AD3: Reserved line, prohibit any operation. | AE3: Reserved line, prohibit any operation. | AF3: Reserved line, prohibit any operation. | AG3: Reserved line, prohibit any operation. | AH3: Reserved line, prohibit any operation. | AI3: Reserved line, prohibit any operation. | AJ3: Reserved line, prohibit any operation. | AK3: Reserved line, prohibit any operation. | AL3: Reserved line, prohibit any operation. | AM3: Reserved line, prohibit any operation. | AN3: Reserved line, prohibit any operation. | AO3: Reserved line, prohibit any operation. | AP3: Reserved line, prohibit any operation. | AQ3: Reserved line, prohibit any operation. | AR3: Reserved line, prohibit any operation. | AS3: Reserved line, prohibit any operation. | AT3: Reserved line, prohibit any operation. | AU3: Reserved line, prohibit any operation. | AV3: Reserved line, prohibit any operation. | AW3: Reserved line, prohibit any operation. | AX3: Reserved line, prohibit any operation. | AY3: Reserved line, prohibit any operation. | AZ3: Reserved line, prohibit any operation. | BA3: Reserved line, prohibit any operation. | BB3: Reserved line, prohibit any operation. | BC3: Reserved line, prohibit any operation. | BD3: Reserved line, prohibit any operation. | BE3: Reserved line, prohibit any operation. | BF3: Reserved line, prohibit any operation. | BG3: Reserved line, prohibit any operation. | BH3: Reserved line, prohibit any operation. | BI3: Reserved line, prohibit any operation. | BJ3: Reserved line, prohibit any operation. | BK3: Reserved line, prohibit any operation. | BL3: Reserved line, prohibit any operation. | BM3: Reserved line, prohibit any operation. | BN3: Reserved line, prohibit any operation. | BO3: Reserved line, prohibit any operation. | BP3: Reserved line, prohibit any operation. | BQ3: Reserved line, prohibit any operation. | BR3: Reserved line, prohibit any operation. | BS3: Reserved line, prohibit any operation. | BT3: Reserved line, prohibit any operation. | BU3: Reserved line, prohibit any operation. | BV3: Reserved line, prohibit any operation. | BW3: Reserved line, prohibit any operation. | BX3: Reserved line, prohibit any operation. | BY3: Reserved line, prohibit any operation. | BZ3: Reserved line, prohibit any operation. | CA3: Reserved line, prohibit any operation. | CB3: Reserved line, prohibit any operation. | CC3: Reserved line, prohibit any operation. | CD3: Reserved line, prohibit any operation. | CE3: Reserved line, prohibit any operation. | CF3: Reserved line, prohibit any operation. | CG3: Reserved line, prohibit any operation. | CH3: Reserved line, prohibit any operation. | CI3: Reserved line, prohibit any operation. | CJ3: Reserved line, prohibit any operation. | CK3: Reserved line, prohibit any operation. | CL3: Reserved line, prohibit any operation. | CM3: Reserved line, prohibit any operation. | CN3: Reserved line, prohibit any operation. | CO3: Reserved line, prohibit any operation. | CP3: Reserved line, prohibit any operation. | CQ3: Reserved line, prohibit any operation. | CR3: Reserved line, prohibit any operation. | CS3: Reserved line, prohibit any operation. | CT3: Reserved line, prohibit any operation. | CU3: Reserved line, prohibit any operation. | CV3: Reserved line, prohibit any operation.
A4: t_0_Goods Id | B4: t_0_Sku Id | C4: t_0_Status | D4: t_0_Details | E4: t_1_Category | F4: t_1_Category Name | G4: t_1_Product type | H4: t_1_Customization processing technique | I4: t_1_Primary technique | J4: t_1_Secondary technique | K4: t_1_Secondary technique | L4: t_1_Product Name | M4: t_1_Contribution Goods | N4: t_1_Contribution SKU | O4: t_1_Update or Add | P4: t_1_Goods Id | Q4: t_1_Sku Id | R4: t_1_Brand | S4: t_1_Trademark | T4: t_2_Product Description | U4: t_2_Bullet Point | V4: t_2_Bullet Point | W4: t_2_Bullet Point | X4: t_2_Bullet Point | Y4: t_2_Bullet Point | Z4: t_2_Bullet Point | AA4: t_2_Detail Images URL | AB4: t_2_Detail Images URL | AC4: t_2_Detail Images URL | AD4: t_2_Detail Images URL | AE4: t_2_Detail Images URL | AF4: t_2_Detail Images URL | AG4: t_2_Detail Images URL | AH4: t_2_Detail Images URL | AI4: t_2_Detail Images URL | AJ4: t_2_Detail Images URL | AK4: t_2_Detail Images URL | AL4: t_2_Detail Images URL | AM4: t_2_Detail Images URL | AN4: t_2_Detail Images URL | AO4: t_2_Detail Images URL | AP4: t_2_Detail Images URL | AQ4: t_2_Detail Images URL | AR4: t_2_Detail Images URL | AS4: t_2_Detail Images URL | AT4: t_2_Detail Images URL | AU4: t_2_Detail Images URL | AV4: t_2_Detail Images URL | AW4: t_2_Detail Images URL | AX4: t_2_Detail Images URL | AY4: t_2_Detail Images URL | AZ4: t_2_Detail Images URL | BA4: t_2_Detail Images URL | BB4: t_2_Detail Images URL | BC4: t_2_Detail Images URL | BD4: t_2_Detail Images URL | BE4: t_2_Detail Images URL | BF4: t_2_Detail Images URL | BG4: t_2_Detail Images URL | BH4: t_2_Detail Images URL | BI4: t_2_Detail Images URL | BJ4: t_2_Detail Images URL | BK4: t_2_Detail Images URL | BL4: t_2_Detail Images URL | BM4: t_2_Detail Images URL | BN4: t_2_Detail Images URL | BO4: t_2_Detail Images URL | BP4: t_2_Detail Images URL | BQ4: t_2_Detail Images URL | BR4: t_2_Detail Images URL | BS4: t_2_Detail Images URL | BT4: t_2_Detail Images URL | BU4: t_2_Detail Images URL | BV4: t_2_Detail Images URL | BW4: t_2_Detail Images URL | BX4: t_2_Detail Images URL | BY4: t_2_Detail Images URL | BZ4: t_2_Detail Images URL | CA4: t_2_Detail Images URL | CB4: t_2_Detail Images URL | CC4: t_2_Detail Images URL | CD4: t_2_Detail Images URL | CE4: t_2_Detail Images URL | CF4: t_2_Detail Images URL | CG4: t_2_Detail Images URL | CH4: t_2_Detail Images URL | CI4: t_2_Detail Images URL | CJ4: t_2_Detail Images URL | CK4: t_2_Detail Images URL | CL4: t_2_Detail Images URL | CM4: t_2_Detail Images URL | CN4: t_2_Detail Images URL | CO4: t_2_Detail Images URL | CP4: t_2_Detail Images URL | CQ4: t_2_Detail Images URL | CR4: t_2_Detail Images URL | CS4: t_2_Detail Images URL | CT4: t_2_Detail Images URL | CU4: t_2_Detail Images URL | CV4: t_2_Detail Images URL | CW4: t_2_Detail Images URL | CX4: t_2_Detail Images URL | CY4: t_2_Detail Images URL | CZ4: t_2_Detail Images URL | DA4: t_2_Detail Images URL | DB4: t_2_Detail Images URL | DC4: t_2_Detail Images URL | DD4: t_2_Detail Images URL | DE4: t_2_Detail Images URL | DF4: t_2_Detail Images URL | DG4: t_2_Detail Images URL | DH4: t_2_Detail Images URL | DI4: t_2_Detail Images URL | DJ4: t_2_Detail Images URL | DK4: t_2_Detail Images URL | DL4: t_2_Detail Images URL | DM4: t_2_Detail Images URL | DN4: t_2_Detail Images URL | DO4: t_2_Detail Images URL | DP4: t_2_Detail Images URL | DQ4: t_2_Detail Images URL | DR4: t_2_Detail Video URL | DS4: t_3_Property:19 | DT4: t_3_Property:423 | DU4: t_3_Property:423 | DV4: t_3_Property:423 | DW4: t_3_Property:423 | DX4: t_3_Property:423 | DY4: t_3_Property:127 | DZ4: t_3_Property:121 | EA4: t_3_Property:130 | EB4: t_3_Property:2232 | EC4: t_3_Property:2233|2232 | ED4: t_3_Property:1561 | EE4: t_3_Property:1132|1561 | EF4: t_3_Property:1562|1561 | EG4: t_3_Property:137|1561 | EH4: t_3_Property:1563|1561 | EI4: t_3_Property:1485|1561 | EJ4: t_3_Property:2147|1561 | EK4: t_3_Property:2154|1561 | EL4: t_3_Property:111|1561 | EM4: t_3_Property:2028 - value|1561 | EN4: t_3_Property:2028 - unit|1561 | EO4: t_3_Property:3673 | EP4: t_3_Property:7644 | EQ4: t_4_Variation Theme | ER4: t_4_Custom Spec:1001 | ES4: t_4_Custom Spec:3001 | ET4: t_4_Custom Spec:18012 | EU4: t_4_Custom Spec:17017 | EV4: t_4_Custom Spec:18013 | EW4: t_4_Custom Spec:17018 | EX4: t_4_Custom Spec:18014 | EY4: t_4_Custom Spec:17019 | EZ4: t_4_Custom Spec:18016 | FA4: t_4_Custom Spec:17020 | FB4: t_4_Custom Spec:15998553 | FC4: t_4_Custom Spec:45114199 | FD4: t_4_Custom Spec:44214483 | FE4: t_6_SKU Images URL | FF4: t_6_SKU Images URL | FG4: t_6_SKU Images URL | FH4: t_6_SKU Images URL | FI4: t_6_SKU Images URL | FJ4: t_6_SKU Images URL | FK4: t_6_SKU Images URL | FL4: t_6_SKU Images URL | FM4: t_6_SKU Images URL | FN4: t_6_SKU Images URL | FO4: t_6_Dimensions | FP4: t_6_Quantity | FQ4: t_6_Base Price - USD | FR4: t_6_Reference Link | FS4: t_6_List Price - USD | FT4: t_6_Weight - lb | FU4: t_6_Length - in | FV4: t_6_Width - in | FW4: t_6_Height - in | FX4: t_6_SKU type | FY4: t_6_Individually packed | FZ4: t_6_Total packaging quantity | GA4: t_6_Packaging unit | GB4: t_6_Total item quantity | GC4: t_6_Item unit | GD4: t_6_Net content | GE4: t_6_Total net content | GF4: t_6_Net content unit | GG4: t_6_External Product ID Type | GH4: t_6_External Product ID | GI4: t_7_Shipping Template | GJ4: t_7_Handling Time | GK4: t_7_Import Designation | GL4: t_7_Fulfillment Channel | GM4: t_8_Country/Region of Origin | GN4: t_8_Province of Origin | GO4: t_8_SKU Packaging Information (with visible label) | GP4: t_8_SKU Packaging Information (with visible label) | GQ4: t_8_SKU Packaging Information (with visible label) | GR4: t_8_SKU Packaging Information (with visible label) | GS4: t_8_SKU Packaging Information (with visible label) | GT4: t_8_SKU Packaging Information (with visible label) | GU4: t_8_SKU Packaging Information (with visible label) | GV4: t_8_SKU Packaging Information (with visible label) | GW4: t_8_SKU Packaging Information (with visible label) | GX4: t_8_SKU Packaging Information (with visible label) | GY4: t_8_SKU Packaging Information (with visible label) | GZ4: t_8_SKU Packaging Information (with visible label) | HA4: t_8_SKU Packaging Information (with visible label) | HB4: t_8_SKU Packaging Information (with visible label) | HC4: t_8_SKU Packaging Information (with visible label) | HD4: t_8_SKU Packaging Information (with visible label) | HE4: t_8_SKU Packaging Information (with visible label) | HF4: t_8_SKU Packaging Information (with visible label) | HG4: t_8_SKU Packaging Information (with visible label) | HH4: t_8_SKU Packaging Information (with visible label) | HI4: t_8_SKU Packaging Information (with visible label) | HJ4: t_8_SKU Packaging Information (with visible label) | HK4: t_8_SKU Packaging Information (with visible label) | HL4: t_8_SKU Packaging Information (with visible label) | HM4: t_8_SKU Packaging Information (with visible label) | HN4: t_8_SKU Packaging Information (with visible label) | HO4: t_8_SKU Packaging Information (with visible label) | HP4: t_8_SKU Packaging Information (with visible label) | HQ4: t_8_SKU Packaging Information (with visible label) | HR4: t_8_SKU Packaging Information (with visible label) | HS4: t_8_SKU Packaging Information (with visible label) | HT4: t_8_SKU Packaging Information (with visible label) | HU4: t_8_SKU Packaging Information (with visible label) | HV4: t_8_SKU Packaging Information (with visible label) | HW4: t_8_SKU Packaging Information (with visible label) | HX4: t_8_SKU Packaging Information (with visible label) | HY4: t_8_SKU Packaging Information (with visible label) | HZ4: t_8_SKU Packaging Information (with visible label) | IA4: t_8_SKU Packaging Information (with visible label) | IB4: t_8_SKU Packaging Information (with visible label) | IC4: t_8_SKU Packaging Information (with visible label) | ID4: t_8_SKU Packaging Information (with visible label) | IE4: t_8_SKU Packaging Information (with visible label) | IF4: t_8_SKU Packaging Information (with visible label) | IG4: t_8_SKU Packaging Information (with visible label) | IH4: t_8_Origin Label & Manufacturer Information | II4: t_8_Origin Label & Manufacturer Information | IJ4: t_8_Origin Label & Manufacturer Information | IK4: t_8_Origin Label & Manufacturer Information | IL4: t_8_Origin Label & Manufacturer Information | IM4: t_8_Product Guide | IN4: t_8_Governance Property:1000000001 | IO4: t_8_Governance Property:1000000002
F5: =IFERROR(VLOOKUP(INDIRECT(ADDRESS(ROW(), COLUMN()-1)), 'Category Name'!$A:$B, 2, FALSE), "Please select the [category] first. After selecting, the full category path will be displayed here. Please do not modify the functions in the cells") -> 0
F6: =IFERROR(VLOOKUP(INDIRECT(ADDRESS(ROW(), COLUMN()-1)), 'Category Name'!$A:$B, 2, FALSE), "Please select the [category] first. After selecting, the full category path will be displayed here. Please do not modify the functions in the cells") -> 0
F7: =IFERROR(VLOOKUP(INDIRECT(ADDRESS(ROW(), COLUMN()-1)), 'Category Name'!$A:$B, 2, FALSE), "Please select the [category] first. After selecting, the full category path will be displayed here. Please do not modify the functions in the cells") -> 0
F8: =IFERROR(VLOOKUP(INDIRECT(ADDRESS(ROW(), COLUMN()-1)), 'Category Name'!$A:$B, 2, FALSE), "Please select the [category] first. After selecting, the full category path will be displayed here. Please do not modify the functions in the cells") -> 0
F9: =IFERROR(VLOOKUP(INDIRECT(ADDRESS(ROW(), COLUMN()-1)), 'Category Name'!$A:$B, 2, FALSE), "Please select the [category] first. After selecting, the full category path will be displayed here. Please do not modify the functions in the cells") -> 0
F10: =IFERROR(VLOOKUP(INDIRECT(ADDRESS(ROW(), COLUMN()-1)), 'Category Name'!$A:$B, 2, FALSE), "Please select the [category] first. After selecting, the full category path will be displayed here. Please do not modify the functions in the cells") -> 0
F11: =IFERROR(VLOOKUP(INDIRECT(ADDRESS(ROW(), COLUMN()-1)), 'Category Name'!$A:$B, 2, FALSE), "Please select the [category] first. After selecting, the full category path will be displayed here. Please do not modify the functions in the cells") -> 0
F12: =IFERROR(VLOOKUP(INDIRECT(ADDRESS(ROW(), COLUMN()-1)), 'Category Name'!$A:$B, 2, FALSE), "Please select the [category] first. After selecting, the full category path will be displayed here. Please do not modify the functions in the cells") -> 0
F13: =IFERROR(VLOOKUP(INDIRECT(ADDRESS(ROW(), COLUMN()-1)), 'Category Name'!$A:$B, 2, FALSE), "Please select the [category] first. After selecting, the full category path will be displayed here. Please do not modify the functions in the cells") -> 0
F14: =IFERROR(VLOOKUP(INDIRECT(ADDRESS(ROW(), COLUMN()-1)), 'Category Name'!$A:$B, 2, FALSE), "Please select the [category] first. After selecting, the full category path will be displayed here. Please do not modify the functions in the cells") -> 0
F15: =IFERROR(VLOOKUP(INDIRECT(ADDRESS(ROW(), COLUMN()-1)), 'Category Name'!$A:$B, 2, FALSE), "Please select the [category] first. After selecting, the full category path will be displayed here. Please do not modify the functions in the cells") -> 0
F16: =IFERROR(VLOOKUP(INDIRECT(ADDRESS(ROW(), COLUMN()-1)), 'Category Name'!$A:$B, 2, FALSE), "Please select the [category] first. After selecting, the full category path will be displayed here. Please do not modify the functions in the cells") -> 0
... F3000: =IFERROR(VLOOKUP(INDIRECT(ADDRESS(ROW(), COLUMN()-1)), 'Category Name'!$A:$B, 2, FALSE), "Please select the [category] first. After selecting, the full category path will be displayed here. Please do not modify the functions in the cells") -> 0

Sheet Instructions
A1: Using your Template
A2: Print this page
A3: On this page, you'll find the necessary details to generate, verify, and submit your template spreadsheet to Temu. For ease of reference throughout the process, we suggest printing out this page.
A4: Save a version of this file on your hard drive in Excel format. Next, input your product information into the Template tab, adhering to the following instructions.
A6: Image Tab
A7: Refer to the Images tab to familiarize yourself with Temu's guidelines for visual content. Ensure that the images you contribute to Temu align with these specified standards to maintain uniformity and excellence.
A8: It's important that an image is supplied for all products. Upload images by providing the image URL.
A10: Example Tab
A11: Check out the Example tab to view a sample of how to input product details. This is provided just for your guidance. Remember, to prevent the incorporation of incorrect product information into your inventory file, you should not edit your own products directly within the Example sheet.
A13: Template Tab
A14: Navigate to the Template tab to populate it with your listing specifics. When you select a Product Type 1. Recommended software: Due to file compatibility considerations, it is recommended to use Office - Excel to use and edit the template file; 2. Template integrity: Do not modify or delete the sheet names, column headers, or their order in the template file. For cells with dropdown enumerations, select and fill in values from the dropdown list. 3. After selecting the category you wish to publish in one row of the template; the file will then automatically display the required fields and valid values for each cell based on the selected category. a. Red borders indicate required fields. b. Gray shading indicates fields that should be left blank. c. White shading indicates optional fields. d. Please ensure that all required information in each row is filled in accurately and completely. Please enter the same product dimension information in all SKU rows. e. Although you don't have to fill in the optional fields, providing as much information as possible will help with product sales. 4. Units of measurement: the units in the template file are related to the publishing site a. The US marketplace uses the imperial system: the length unit is inches, the weight unit is pounds, and the currency unit is USD i. The length range is 0.1 in-999.9 in, with a maximum of 1 decimal point, and will be rounded up; ii. The weight range is 0.1 lb-9999.9 lb, with a maximum of 1 decimal point, and will be rounded up; iii. The price range is $0.01-$99999999.99, with a maximum of 2 decimal points, and will be rounded up. b. The Mexican marketplace uses the metric system: the length unit is centimeters, the weight unit is grams, and the currency unit is MXN i. The length range is 0.1 cm-9,999.9 cm, with a maximum of 1 decimal point, and will be rounded up; ii. The weight range is 0.1 g-9,999,999.9 g, with a maximum of 1 decimal place, and will be rounded up; iii. The price range is MX$0.01-MX$99999999.99, with a maximum of 2 decimal points, and will be rounded up. c. The Japan marketplace uses the metric system: the length unit is centimeters, the weight unit is grams, and the currency unit is JPY i. The length range is 0.1 cm-9,999.9 cm, with a maximum of 1 decimal point, and will be rounded up; ii. The weight range is 0.1 g-9,999,999.9 g, with a maximum of 1 decimal place, and will be rounded up; iii. The price range is 円1-円9,999,999,999, with a maximum of 0 decimal points, and will be rounded up. d. The German, Italian, French and Spanish marketplaces all use the metric system: the length unit is centimeters, the weight unit is grams, and the currency unit is EUR i. The length range is 0.1 cm-9,999.9 cm, with a maximum of 1 decimal point, and will be rounded up; ii. The weight range is 0.1 g-9,999,999.9 g, with a maximum of 1 decimal place, and will be rounded up; iii. The price range is €0.01-€99999999.99, with a maximum of 2 decimal places, and will be rounded up. e. Marketplace in UK is metric: the length unit is centimeters, the weight unit is grams, and the currency unit is GBP i. The length range is 0.1 cm-9,999.9 cm, with a maximum of 1 decimal point, and will be rounded up; ii. The weight range is 0.1 g-9,999,999.9 g, with a maximum of 1 decimal place, and will be rounded up; iii. The price range is £0.01-£99999999.99, with a maximum of 2 decimal places, and will be rounded up. 5. Qualifications and photos: Different compliance requirements may be imposed under varying conditions during the product's ongoing operation. For products that require these materials, you can submit the documents and then access the product compliance center to confirm and provide them. 6. Quantity limit: In each file, up to 2000 lines of content are allowed, otherwise products will not be able to be added to the file. Alternatively, you can save the "Template" tab (only) as Unicode Text (*.txt)): right-click the "Template" tab, move or copy, select "New book" and "Create a Copy," then choose "File" and save in the correct file format. Files uploaded this way can contain up to 50,000 lines. 7. Duplicate columns: The Excel file is collapsed by default. You can click on 1 and 2 at the top of the Excel file.
A17: Submit the spreadsheet
... A23: From time to time, Temu will update valid values, data validation rules, explanatory text, and requirements. Please use the latest generated template files.

Sheet Images
A1: Image Standards
A3: Every product on Temu needs one or more product images. Choose images that are clear, straightforward, and easy to understand. They must accurately represent the product and be information-rich and attractively presented. Show only the product that is being offered for sale. Whenever possible, provide several images, with each one showing different angles and details of the product. This is your opportunity to show your product to your customer, so quality matters.
A4: We reserve the right to reject images that do not meet our image standards.
A5: It is your responsibility to ensure that you have all necessary rights to the images you submit.
A7: SKU images
A9: The SKU images will be displayed at the top of the product page. Different SKU images will form a carousel of the product.
A10: For apparel products, the images you upload should be with a maximum size of 3MB, an aspect ratio of 3:4, width ≥ 1340px, height ≥ 1785px. The SKUs with the same color will share a set of carousel images.
A11: For non-apparel products, the images you upload should be with a maximum size of 3MB, an aspect ratio of 1:1, and width and height ≥ 800px.
A12: You can upload up to ten images, with each cell containing one image URL.
A14: Product video
A16: The product video will be displayed at the top of the product page.
A17: The video you upload should be with a maximum size of 100MB, a length not exceeding 180 seconds, and a minimum resolution of 720P.
... A32: Upload the video with a maximum size of 300MB, a length not exceeding 180 seconds, an aspect ratio of either 1:1, 4:3, or 16:9, and a minimum resolution of 720P.

Sheet Example
A1: 1. Besides reviewing the contents of the Example tab, kindly peruse the Instructions tab provided in this document.
A2: 2. Be aware that the examples provided serve merely as illustrations. The columns appearing in your tailored template will vary according to the selected Category. Utilize the Template tab to generate the template spreadsheet.
A3: 3. Some of the optional columns are collapsed for the purpose of better representation. Please show those collapsed areas by clicking '+' button on the corresponding column or section
A4: 4. Errors when you submit a product entry can be resolved by viewing the Processing results, or by contacting Seller Support.
A5: Some fields are Required. Other are Optional. | B5: Product Identity | H5: Product Description | BN5: Product Detail | GT5: Sale Property (At Least One, At Most Two) | HL5: Size Chart | IE5: Variations | IZ5: Offer | JD5: Qualifications
B6: Category | C6: Product Name | D6: Contribution Goods | E6: Contribution SKU | F6: Brand | G6: Trademark | H6: Product Description | I6: Bullet Point | J6: Bullet Point | K6: Bullet Point | L6: Bullet Point | M6: Bullet Point | N6: Bullet Point | O6: Detail Images URL | P6: Detail Images URL | Q6: Detail Images URL | R6: Detail Images URL | S6: Detail Images URL | T6: Detail Images URL | U6: Detail Images URL | V6: Detail Images URL | W6: Detail Images URL | X6: Detail Images URL | Y6: Detail Images URL | Z6: Detail Images URL | AA6: Detail Images URL | AB6: Detail Images URL | AC6: Detail Images URL | AD6: Detail Images URL | AE6: Detail Images URL | AF6: Detail Images URL | AG6: Detail Images URL | AH6: Detail Images URL | AI6: Detail Images URL | AJ6: Detail Images URL | AK6: Detail Images URL | AL6: Detail Images URL | AM6: Detail Images URL | AN6: Detail Images URL | AO6: Detail Images URL | AP6: Detail Images URL | AQ6: Detail Images URL | AR6: Detail Images URL | AS6: Detail Images URL | AT6: Detail Images URL | AU6: Detail Images URL | AV6: Detail Images URL | AW6: Detail Images URL | AX6: Detail Images URL | AY6: Detail Images URL | AZ6: Detail Images URL | BA6: Detail Images URL | BB6: Detail Images URL | BC6: Detail Images URL | BD6: Detail Images URL | BE6: Detail Images URL | BF6: Detail Images URL | BG6: Detail Images URL | BH6: Detail Images URL | BI6: Detail Images URL | BJ6: Detail Images URL | BK6: Detail Images URL | BL6: Detail Images URL | BM6: Detail Video URL | BN6: 4115 - Shelf Life - value | BO6: 4115 - Shelf Life - unit | BP6: 4118 - Speciality | BQ6: 4118 - Speciality | BR6: 4118 - Speciality | BS6: 4119 - Item Weight - value | BT6: 4119 - Item Weight - unit | BU6: 4120 - Package Weight - value | BV6: 4120 - Package Weight - unit | BW6: 4121 - Allergen Information | BX6: 4121 - Allergen Information | BY6: 4121 - Allergen Information | BZ6: 4121 - Allergen Information | CA6: 4121 - Allergen Information | CB6: 4121 - Allergen Information | CC6: 4121 - Allergen Information | CD6: 4121 - Allergen Information | CE6: 4121 - Allergen Information | CF6: 4121 - Allergen Information | CG6: 195 - Diet Type | CH6: 195 - Diet Type | CI6: 195 - Diet Type | CJ6: 6160 - Brand Name | CK6: 6210 - USDA certified | CL6: 4110 - Production Date | CM6: 6440 - best before | CN6: 361 - Package Quantity | CO6: 12 - Material | CP6: 12 - Material | CQ6: 12 - Material | CR6: 12 - Material | CS6: 12 - Material | CT6: 4134 - Publisher | CU6: 4130 - Country/Region Of Origin | CV6: 4137 - Author | CW6: 1120 - Set or not | CX6: 4133 - Binding Type | CY6: 4123 - Languages | CZ6: 4123 - Languages | DA6: 4123 - Languages | DB6: 4142 - Year Of Publication | DC6: 4124 - Number Of Pages (pages) - value | DD6: 4124 - Number Of Pages (pages) - unit | DE6: 4131 - Number Of Words (10,000 Words) | DF6: 4127 - Product Weight (g) - value | DG6: 4127 - Product Weight (g) - unit | DH6: 4128 - Maximum Reading Age (years) - value | DI6: 4128 - Maximum Reading Age (years) - unit | DJ6: 4129 - Minimum Reading Age (years) - value | DK6: 4129 - Minimum Reading Age (years) - unit | DL6: 121 - Material | DM6: 121 - Material | DN6: 121 - Material | DO6: 121 - Material | DP6: 121 - Material | DQ6: 132 - Finish Type | DR6: 210 - Furniture Finish | DS6: 19 - Style | DT6: 1561 - Power Supply | DU6: 1132 - Operating Voltage | DV6: 1485 - Plug Type | DW6: 1485 - Plug Type | DX6: 1485 - Plug Type | DY6: 1571 - Acceptable Voltage Range | DZ6: 4102 - Contain Wooden Materials | EA6: 4097 - Tree Species | EB6: 4097 - Tree Species | EC6: 4098 - Wood Formation Type | ED6: 4098 - Wood Formation Type | EE6: 4098 - Wood Formation Type | EF6: 4099 - Fiberboard Density | EG6: 6171 - Wether Independent | EH6: 6172 - Closed Storage Capacity | EI6: 6173 - Height After Assembly | EJ6: 6174 - Physical Weight | EK6: 2153 - Battery Properties | EL6: 2147 - Rechargeable Battery | EM6: 2154 - Solar Battery Type | EN6: 3740 - Non-rechargeable Battery | EO6: 2028 - Battery Capacity (mAh) - value | EP6: 2028 - Battery Capacity (mAh) - unit | EQ6: 63 - Color | ER6: 15 - Composition:Nylon | ES6: 15 - Composition:Polyester | ET6: 15 - Composition:Polyamide | EU6: 15 - Composition:Elastane | EV6: 15 - Composition:Spandex | EW6: 15 - Composition:Acrylic | EX6: 15 - Composition:Cotton | EY6: 15 - Composition:Silk | EZ6: 15 - Composition:Linen | FA6: 15 - Composition:Modal | FB6: 15 - Composition:Viscose | FC6: 15 - Composition:Rayon | FD6: 15 - Composition:Carbon | FE6: 15 - Composition:Metal | FF6: 15 - Composition:Wool | FG6: 15 - Composition:Cashmere | FH6: 15 - Composition:Mohair | FI6: 15 - Composition:Rabbit Hair | FJ6: 15 - Composition:Bovine Leather | FK6: 15 - Composition:Sheep Leather | FL6: 15 - Composition:Pig Leather | FM6: 15 - Composition:Polyurethane | FN6: 15 - Composition:Polyvinyl Chloride | FO6: 15 - Composition:Cupro | FP6: 15 - Composition:Lyocell | FQ6: 15 - Composition:Acetate | FR6: 15 - Composition:Down | FS6: 15 - Composition:Feather | FT6: 15 - Composition:Duck Down | FU6: 15 - Composition:Alpaca | FV6: 15 - Composition:Metallized Fibres | FW6: 15 - Composition:Polypropylene fibers | FX6: 15 - Composition:Other Fibers | FY6: 28 - Length | FZ6: 74 - Belt | GA6: 29 - Sleeve Length | GB6: 27 - Sleeve Type | GC6: 94 - Chest Pad | GD6: 83 - Details | GE6: 26 - Pattern | GF6: 24 - Sheer | GG6: 22 - Fabric | GH6: 86 - Placket Type | GI6: 78 - Lining | GJ6: 113 - Contour | GK6: 76 - Season | GL6: 20 - Operation Instruction | GM6: 114 - Fit Type | GN6: 1352 - Fabric Elasticity | GO6: 1919 - Printing Type | GP6: 2103 - Style source | GQ6: 1192 - Weaving Method | GR6: 21 - Collar Style | GS6: 6227 - Collection | GT6: Variation Theme | GU6: Size Family | GV6: Sub-Size Family | GW6: Size | GX6: Color | GY6: Color | GZ6: Size | HA6: Style | HB6: Material | HC6: Flavors | HD6: Applicable People | HE6: Capacity | HF6: Composition | HG6: Weight | HH6: Items | HI6: Quantity | HJ6: Model | HK6: Hair Length | HL6: Unit | HM6: US Size | HN6: Tops - Product - Shoulder width | HO6: Tops - Product - Bust size | HP6: Tops - Product - Clothes length | HQ6: Tops - Product - Sleeve length | HR6: Tops - Product - Waist size | HS6: Tops - Product - Underbust | HT6: Tops - Product - Neck | HU6: Tops - Product - Hem | HV6: Tops - Product - Cuffs | HW6: Tops - Body - Bust - min | HX6: Tops - Body - Bust - max | HY6: Tops - Body - Waist - min | HZ6: Tops - Body - Waist - max | IA6: Tops - Body - Hips - min | IB6: Tops - Body - Hips - max | IC6: Tops - Body - Height - min | ID6: Tops - Body - Height - max | IE6: SKU Images URL | IF6: SKU Images URL | IG6: SKU Images URL | IH6: SKU Images URL | II6: SKU Images URL | IJ6: SKU Images URL | IK6: SKU Images URL | IL6: SKU Images URL | IM6: SKU Images URL | IN6: SKU Images URL | IO6: Dimensions | IP6: Condition | IQ6: Quantity | IR6: Base Price - USD | IS6: List Price - USD | IT6: Weight - lb | IU6: Length - in | IV6: Width - in | IW6: Height - in | IX6: External Product ID Type | IY6: External Product ID | IZ6: Handling Time | JA6: Shipping Template | JB6: Import Designation | JC6: Fulfillment Channel | JD6: Product Guide | JE6: California Proposition 65 Warning Type | JF6: California Proposition 65 Warning Type | JG6: California Proposition 65 Warning Type | JH6: California Proposition 65 Chemical Names | JI6: California Proposition 65 Chemical Names | JJ6: California Proposition 65 Chemical Names | JK6: California Proposition 65 Chemical Names | JL6: California Proposition 65 Chemical Names | JM6: California Proposition 65 Chemical Names | JN6: California Proposition 65 Chemical Names | JO6: California Proposition 65 Chemical Names | JP6: California Proposition 65 Chemical Names | JQ6: California Proposition 65 Chemical Names | JR6: California Proposition 65 Chemical Names | JS6: California Proposition 65 Chemical Names | JT6: California Proposition 65 Chemical Names | JU6: California Proposition 65 Chemical Names | JV6: California Proposition 65 Chemical Names | JW6: California Proposition 65 Chemical Names | JX6: California Proposition 65 Chemical Names | JY6: California Proposition 65 Chemical Names | JZ6: California Proposition 65 Chemical Names | KA6: California Proposition 65 Chemical Names
A7: Example 1: This is an example of providing a new listing. This example has no variation and is listed as a single detail page. | B7: 29069 | C7: Example Women T-shirt, 156 Black T-shirt | D7: EXAMPLE-156-US-Black-one-size | E7: EXAMPLE-156-US-Black-one-size | H7: Unleash your personal style with our classic fit tee. Crafted from 100% cotton, it offers unmatched comfort and durability. The tee features a unique, eye-catching graphic that embodies modern chic. Perfect for casual outings or layering under a jacket, this T-shirt is versatile for any occasion. With a breathable fabric that holds its shape, it's a wardrobe staple you'll reach for time and again. Make a statement and stay cozy in a shirt designed to express who you are. (Character count: 493) | I7: 100% premium cotton for ultimate comfort. | J7: Timeless design meets modern style. | K7: Durable fabric, perfect for daily wear | L7: Machine washable and easy to care for. | M7: Versatile fit for every body type. | O7: http://www.companyname.com/images/1250.main.jpg | P7: http://www.companyname.com/images/1250.main.jpg | Q7: http://www.companyname.com/images/1250.main.jpg | R7: http://www.companyname.com/images/1250.main.jpg | CO7: Recycle Polyester | DS7: Y2K | ER7: 32 | ES7: 28 | ET7: 40 | FY7: Short Length | FZ7: Yes | GA7: Long Sleeve | GB7: Raglan sleeve | GC7: No Padding | GD7: Fake Pockets | GE7: Mushroom | GF7: No | GG7: Non-Stretch | GH7: Half Placket | GI7: Cashmere | GJ7: H | GK7: Fall | GL7: Do not wash | GM7: Regular | GN7: No Elasticity | GO7: Positioning Printing | GP7: Buyer provides | GQ7: Woven | GR7: Off the Shoulder | GS7: Middle East | GT7: Size × Color | GU7: US/EU size | GV7: One Size | GW7: one-size | GX7: Black | HL7: Inch | HM7: one-size | HO7: 36 | HP7: 28 | HW7: 33.9 | HX7: 35.5 | HY7: 26 | HZ7: 27.6 | IA7: 35.9 | IB7: 37.4 | IE7: http://www.companyname.com/images/1250.main.jpg | IF7: http://www.companyname.com/images/1250.main.jpg | IG7: http://www.companyname.com/images/1250.main.jpg | IO7: http://www.companyname.com/images/1250.main.jpg | IP7: Used - Like new | IQ7: 5 | IR7: 2.99 | IS7: 5.99 | IT7: 9.2 | IU7: 2 | IV7: 3 | IW7: 4 | IZ7: 1 Day | JA7: test1 | JB7: Imported | JC7: I will ship this item myself | JE7: No Warning Applicable
B8: 12408 | C8: Example reclaimed Cabinet Solid Wood with 4 Drawers | D8: EXAMPLE-576-Brown | E8: EXAMPLE-576-Brown | DL8: Wood | DQ8: Painted | DR8: Cedar | DS8: Vintage | DT8: Plug Powered | DU8: 110V (included)-240V (included) | DV8: US Plug | DZ8: Yes | EA8: Hardwood | EC8: Block Board (large Core Board) | EG8: Yes | EH8: <3.2 Cubic Feet | EI8: <27 Inches | EJ8: <30 Lbs | EK8: Without Battery | EQ8: Red | GT8: Color × Style | GY8: Red | HA8: Vintage | IE8: http://www.companyname.com/images/1250.main.jpg | IF8: http://www.companyname.com/images/1250.main.jpg | IG8: http://www.companyname.com/images/1250.main.jpg | IO8: http://www.companyname.com/images/1250.main.jpg | IP8: Used - Very good | IQ8: 0 | IR8: 2.99 | IS8: 5.99 | IT8: 9.2 | IU8: 2 | IV8: 3 | IW8: 4 | IZ8: 1 Day | JA8: test1 | JB8: Imported | JC8: I will ship this item myself | JD8: http://www.companyname.com/images/productguide.pdf | JE8: Chemical | JF8: On Product Cancer | JH8: A-alpha-C (2-Amino-9H-pyrido[2,3-b]indole) | JI8: Acetaldehyde
B9: 44936 | C9: Example book for US with isbn | D9: EXAMPLEISBN9787040205190 | E9: EXAMPLEISBN9787040205190 | CT9: Example publisher | CU9: USA | CV9: Example author | CW9: No | CX9: Paperback | CY9: English | DB9: 44604 | DC9: 300 | DD9: Page | DE9: 1000 | DF9: 200 | DG9: g | DH9: 99 | DI9: years old | DJ9: 1 | DK9: years old | GT9: Items | HH9: Example book for US with isbn | IE9: http://www.companyname.com/images/1250.main.jpg | IF9: http://www.companyname.com/images/1250.main.jpg | IG9: http://www.companyname.com/images/1250.main.jpg | IO9: http://www.companyname.com/images/1250.main.jpg | IP9: Used - Good | IQ9: 20 | IR9: 7.82 | IS9: 10.23 | IT9: 9.2 | IU9: 2 | IV9: 3 | IW9: 4 | IX9: ISBN | IY9: 920000021 | IZ9: 1 Day | JA9: test1 | JB9: Imported | JC9: I will ship this item myself | JE9: No Warning Applicable
B10: 42550 | C10: Example food Potato Chips Pack of 6 - 80g per bag | D10: EXAMPLE-Pack6 - 80g | E10: EXAMPLE-Pack6 - 80g | BN10: 30 | BO10: Day | BP10: Wild-Caught | BQ10: Certified-Humane-Raised-And-Handled | BS10: 90 | BT10: g | BU10: 106 | BV10: g | BW10: Contains cow's milk | BX10: Contains Peanuts | CG10: Plant Based | CJ10: Example brand name | CK10: less than 70% organic ingredients | CL10: 45550 | CM10: 45641 | GT10: Weight | HG10: 90g | IE10: http://www.companyname.com/images/1250.main.jpg | IF10: http://www.companyname.com/images/1250.main.jpg | IG10: http://www.companyname.com/images/1250.main.jpg | IO10: http://www.companyname.com/images/1250.main.jpg | IP10: Used - Acceptable | IQ10: 20 | IR10: 5.39 | IS10: 7.39 | IT10: 9.2 | IU10: 2 | IV10: 3 | IW10: 4 | IZ10: 1 Day | JA10: test1 | JB10: Imported | JC10: I will ship this item myself | JE10: Food
A12: Example 2: This is an example of a product with 1 variation theme (i.e., size) with 3 variations. These are 3 "Child" SKUs in a "Parent" Goods. Note: For product-level information such as Product Name, Product Description, Product Detail, Offer, Qualifications, please ensure that each line is filled out correctly and the information is consistently entered. | B12: 29069 | C12: Example Women T-shirt, 156 Black T-shirt | D12: EXAMPLE-156-US-Black | E12: EXAMPLE-156-US-Black-S | H12: Unleash your personal style with our classic fit tee. Crafted from 100% cotton, it offers unmatched comfort and durability. The tee features a unique, eye-catching graphic that embodies modern chic. Perfect for casual outings or layering under a jacket, this T-shirt is versatile for any occasion. With a breathable fabric that holds its shape, it's a wardrobe staple you'll reach for time and again. Make a statement and stay cozy in a shirt designed to express who you are. (Character count: 493) | I12: 100% premium cotton for ultimate comfort. | J12: Timeless design meets modern style. | K12: Durable fabric, perfect for daily wear | L12: Machine washable and easy to care for. | M12: Versatile fit for every body type. | O12: http://www.companyname.com/images/1250.main.jpg | P12: http://www.companyname.com/images/1250.main.jpg | Q12: http://www.companyname.com/images/1250.main.jpg | R12: http://www.companyname.com/images/1250.main.jpg | CO12: Recycle Polyester | DS12: Y2K | ER12: 32 | ES12: 28 | ET12: 40 | FY12: Short Length | FZ12: Yes | GA12: Long Sleeve | GB12: Raglan sleeve | GC12: No Padding | GD12: Fake Pockets | GE12: Mushroom | GF12: No | GG12: Non-Stretch | GH12: Half Placket | GI12: Cashmere | GJ12: H | GK12: Fall | GL12: Do not wash | GM12: Regular | GN12: No Elasticity | GO12: Positioning Printing | GP12: Buyer provides | GQ12: Woven | GR12: Off the Shoulder | GS12: Middle East | GT12: Size × Color | GU12: US/EU size | GV12: Alpha | GW12: S | GX12: Black | HL12: Inch | HM12: 0 | HO12: 36 | HP12: 28 | HW12: 33.9 | HX12: 35.5 | HY12: 26 | HZ12: 27.6 | IA12: 35.9 | IB12: 37.4 | IE12: http://www.companyname.com/images/1250.main.jpg | IF12: http://www.companyname.com/images/1250.main.jpg | IG12: http://www.companyname.com/images/1250.main.jpg | IO12: http://www.companyname.com/images/1250.main.jpg | IP12: Used - Like new | IQ12: 5 | IR12: 2.99 | IS12: 5.99 | IT12: 9.2 | IU12: 2 | IV12: 3 | IW12: 4 | IZ12: 1 Day | JA12: test1 | JB12: Imported | JC12: I will ship this item myself | JE12: No Warning Applicable
B13: 29069 | C13: Example Women T-shirt, 156 Black T-shirt | D13: EXAMPLE-156-US-Black | E13: EXAMPLE-156-US-Black-M | H13: Unleash your personal style with our classic fit tee. Crafted from 100% cotton, it offers unmatched comfort and durability. The tee features a unique, eye-catching graphic that embodies modern chic. Perfect for casual outings or layering under a jacket, this T-shirt is versatile for any occasion. With a breathable fabric that holds its shape, it's a wardrobe staple you'll reach for time and again. Make a statement and stay cozy in a shirt designed to express who you are. (Character count: 493) | I13: 100% premium cotton for ultimate comfort. | J13: Timeless design meets modern style. | K13: Durable fabric, perfect for daily wear | L13: Machine washable and easy to care for. | M13: Versatile fit for every body type. | O13: http://www.companyname.com/images/1250.main.jpg | P13: http://www.companyname.com/images/1250.main.jpg | Q13: http://www.companyname.com/images/1250.main.jpg | R13: http://www.companyname.com/images/1250.main.jpg | CO13: Recycle Polyester | DS13: Y2K | ER13: 32 | ES13: 28 | ET13: 40 | FY13: Short Length | FZ13: Yes | GA13: Long Sleeve | GB13: Raglan sleeve | GC13: No Padding | GD13: Fake Pockets | GE13: Mushroom | GF13: No | GG13: Non-Stretch | GH13: Half Placket | GI13: Cashmere | GJ13: H | GK13: Fall | GL13: Do not wash | GM13: Regular | GN13: No Elasticity | GO13: Positioning Printing | GP13: Buyer provides | GQ13: Woven | GR13: Off the Shoulder | GS13: Middle East | GT13: Size × Color | GU13: US/EU size | GV13: Alpha | GW13: M | GX13: Black | HL13: Inch | HM13: 2 | HO13: 40 | HP13: 29 | HW13: 35.5 | HX13: 37 | HY13: 27.6 | HZ13: 29.2 | IA13: 27.4 | IB13: 39 | IE13: http://www.companyname.com/images/1250.main.jpg | IF13: http://www.companyname.com/images/1250.main.jpg | IG13: http://www.companyname.com/images/1250.main.jpg | IO13: http://www.companyname.com/images/1250.main.jpg | IP13: Used - Like new | IQ13: 5 | IR13: 2.99 | IS13: 5.99 | IT13: 9.2 | IU13: 2 | IV13: 3 | IW13: 4 | IZ13: 1 Day | JA13: test1 | JB13: Imported | JC13: I will ship this item myself | JE13: No Warning Applicable
B14: 29069 | C14: Example Women T-shirt, 156 Black T-shirt | D14: EXAMPLE-156-US-Black | E14: EXAMPLE-156-US-Black-L | H14: Unleash your personal style with our classic fit tee. Crafted from 100% cotton, it offers unmatched comfort and durability. The tee features a unique, eye-catching graphic that embodies modern chic. Perfect for casual outings or layering under a jacket, this T-shirt is versatile for any occasion. With a breathable fabric that holds its shape, it's a wardrobe staple you'll reach for time and again. Make a statement and stay cozy in a shirt designed to express who you are. (Character count: 493) | I14: 100% premium cotton for ultimate comfort. | J14: Timeless design meets modern style. | K14: Durable fabric, perfect for daily wear | L14: Machine washable and easy to care for. | M14: Versatile fit for every body type. | O14: http://www.companyname.com/images/1250.main.jpg | P14: http://www.companyname.com/images/1250.main.jpg | Q14: http://www.companyname.com/images/1250.main.jpg | R14: http://www.companyname.com/images/1250.main.jpg | CO14: Recycle Polyester | DS14: Y2K | ER14: 32 | ES14: 28 | ET14: 40 | FY14: Short Length | FZ14: Yes | GA14: Long Sleeve | GB14: Raglan sleeve | GC14: No Padding | GD14: Fake Pockets | GE14: Mushroom | GF14: No | GG14: Non-Stretch | GH14: Half Placket | GI14: Cashmere | GJ14: H | GK14: Fall | GL14: Do not wash | GM14: Regular | GN14: No Elasticity | GO14: Positioning Printing | GP14: Buyer provides | GQ14: Woven | GR14: Off the Shoulder | GS14: Middle East | GT14: Size × Color | GU14: US/EU size | GV14: Alpha | GW14: L | GX14: Black | HL14: Inch | HM14: 4 | HO14: 44 | HP14: 30 | HW14: 37.4 | HX14: 39.8 | HY14: 29.6 | HZ14: 31.9 | IA14: 39.4 | IB14: 41.8 | IE14: http://www.companyname.com/images/1250.main.jpg | IF14: http://www.companyname.com/images/1250.main.jpg | IG14: http://www.companyname.com/images/1250.main.jpg | IO14: http://www.companyname.com/images/1250.main.jpg | IP14: Used - Like new | IQ14: 5 | IR14: 2.99 | IS14: 5.99 | IT14: 9.2 | IU14: 2 | IV14: 3 | IW14: 4 | IZ14: 1 Day | JA14: test1 | JB14: Imported | JC14: I will ship this item myself | JE14: No Warning Applicable
B15: 12408 | C15: Example reclaimed Cabinet Solid Wood with 4 Drawers | D15: EXAMPLE-576 | E15: EXAMPLE-576-Brown | DL15: Wood | DQ15: Painted | DR15: Cedar | DS15: Vintage | DT15: Plug Powered | DU15: 110V (included)-240V (included) | DV15: US Plug | DZ15: Yes | EA15: Hardwood | EC15: Block Board (large Core Board) | EG15: Yes | EH15: <3.2 Cubic Feet | EI15: <27 Inches | EJ15: <30 Lbs | EK15: Without Battery | EQ15: Red | GT15: Color | GY15: Brown | IE15: http://www.companyname.com/images/1250.main.jpg | IF15: http://www.companyname.com/images/1250.main.jpg | IG15: http://www.companyname.com/images/1250.main.jpg | IO15: http://www.companyname.com/images/1250.main.jpg | IP15: Used - Very good | IQ15: 5 | IR15: 2.99 | IS15: 5.99 | IT15: 9.2 | IU15: 2 | IV15: 3 | IW15: 4 | IZ15: 1 Day | JA15: test1 | JB15: Imported | JC15: I will ship this item myself | JE15: No Warning Applicable
B16: 12408 | C16: Example reclaimed Cabinet Solid Wood with 4 Drawers | D16: EXAMPLE-576 | E16: EXAMPLE-576-white | DL16: Wood | DQ16: Painted | DR16: Cedar | DS16: Vintage | DT16: Plug Powered | DU16: 110V (included)-240V (included) | DV16: US Plug | DZ16: Yes | EA16: Hardwood | EC16: Block Board (large Core Board) | EG16: Yes | EH16: <3.2 Cubic Feet | EI16: <27 Inches | EJ16: <30 Lbs | EK16: Without Battery | EQ16: Red | GT16: Color | GY16: white | IE16: http://www.companyname.com/images/1250.main.jpg | IF16: http://www.companyname.com/images/1250.main.jpg | IG16: http://www.companyname.com/images/1250.main.jpg | IO16: http://www.companyname.com/images/1250.main.jpg | IP16: Used - Very good | IQ16: 5 | IR16: 2.99 | IS16: 5.99 | IT16: 9.2 | IU16: 2 | IV16: 3 | IW16: 4 | IZ16: 1 Day | JA16: test1 | JB16: Imported | JC16: I will ship this item myself | JE16: No Warning Applicable
B17: 12408 | C17: Example reclaimed Cabinet Solid Wood with 4 Drawers | D17: EXAMPLE-576 | E17: EXAMPLE-576-red | DL17: Wood | DQ17: Painted | DR17: Cedar | DS17: Vintage | DT17: Plug Powered | DU17: 110V (included)-240V (included) | DV17: US Plug | DZ17: Yes | EA17: Hardwood | EC17: Block Board (large Core Board) | EG17: Yes | EH17: <3.2 Cubic Feet | EI17: <27 Inches | EJ17: <30 Lbs | EK17: Without Battery | EQ17: Red | GT17: Color | GY17: red | IE17: http://www.companyname.com/images/1250.main.jpg | IF17: http://www.companyname.com/images/1250.main.jpg | IG17: http://www.companyname.com/images/1250.main.jpg | IO17: http://www.companyname.com/images/1250.main.jpg | IP17: Used - Very good | IQ17: 5 | IR17: 2.99 | IS17: 5.99 | IT17: 9.2 | IU17: 2 | IV17: 3 | IW17: 4 | IZ17: 1 Day | JA17: test1 | JB17: Imported | JC17: I will ship this item myself | JE17: No Warning Applicable
